Workbook
Name DATE: #REF!

Sheet Sheet1
B3: ticker: | C3: HRHO | D3: =VLOOKUP(C3,SOURCE!$G$3:$H$104,2,FALSE) -> مجموعة اي اف جي القابضة | J3: Liquidity ratios
B4: Consolidated Balance Sheet as at | E4: JUNE | F4: 2024 | G4: YEAR | J4: Current Ratio | M4: =(E14/E23) -> 1.230803
B5: Assets | J5: Quick Ratio (Inventory) | M5: =((E14-E9)/E23) -> 0.94921422
B6: Non-current asset | J6: Quick Ratio (Accounts Receivable) | M6: =((E14-E10)/E23) -> 0.36114837
B7: Total Non-current assets | E7: 2406959000 | J7: Cash Ratio | M7: =(E12/E23) -> 0.27753068
B8: Current assets | J8: Net working capital | M8: =(E14-E23) -> 8794259000
B9: Inventory | E9: 10729343000 | J9: Net working capital ratio | M9: =(M8/E23) -> 0.23080305
B10: account and notes receivadles | E10: 33136341000 | J10: Debt ratios
B11: debtors and other depit balances | E11: 45566677000 | J11: Total Debt-to-Total Assets Ratio | M11: =(E24/E15) -> 0.87039917
B12: cach and cach equivalents | E12: 10574716000 | J12: Total debt / Equity | M12: =(E24/E18) -> 2.3377709
B13: others | J13: Total current liabilities/ Equity | M13: =(E23/E18) -> 2.0756697
B14: Total Current assets | E14: 46897131000 | J14: Equity/Total Non-current assets | M14: =(E18/E7) -> 7.6265965
B15: Total assets | E15: =(E7+E14) -> 49304090000 | J15: Interest Coverage Ratio | M15: =(E31/E30) -> #DIV/0!
B16: Liabilities and Share holders equity | J16: Activity Ratios
B17: Share holders' Equity | J17: Inventory Turnover | M17: =(E28/E9) -> 2.0698373
B18: Total equity | E18: 18356905000 | J18: Days Inventory Outstanding (DIO) | M18: =(E56/M17) -> 43.481679
B19: Liabilities | J19: Accounts Receivable Turnover | M19: =(E27/E10) -> 0.78501416
B20: Non-current liabilities | J20: Days Sales Outstanding (DSO) | M20: =(E56/M19) -> 114.64761
B21: Total Non-cerrent liabilites | E21: 4811367000 | J21: Payable Turnover
B22: Current liabilities | J22: Days Payable Outstanding (DPO) | M22: =(M21/E56) -> 0
B23: Total cerrent liabilites | E23: 38102872000 | J23: Operating Cycle (oc) | M23: =M18+M20 -> 158.12929
B24: Total liabilities | E24: =(E21+E23) -> 42914239000 | J24: Cash Conversion Cycle (ccc) | M24: =((M18+M20)-M22) -> 158.12929
B25: Total liabilities and equity | E25: =(E18+E24) -> 61271144000 | J25: Total Non-current assets Turnover | M25: =(E27/E7) -> 10.807204
B26: Income Statement for the period ended | E26: =(E4) -> JUNE | F26: =F4 -> 2024 | G26: =(G4) -> YEAR | J26: Total Current assets Turnover | M26: =(E27/E14) -> 0.55467139
B27: Total Revenue | E27: 26012497000 | J27: Total Asset Turnover | M27: =(E27/E15) -> 0.52759309
B28: Cost of Goods Sold | E28: 22207994000 | J28: Profitability ratios
B29: Gross Profit | E29: =(E27-E28) -> 3804503000 | J29: Gross Margin Ratio | M29: =(E29/E27) -> 0.14625674
B30: Other Revenues | J30: Return on Assets (ROA) | M30: =(E41/E15) -> 0
B31: interest expense | E31: -293704000 | J31: Return on Equity (ROE) | M31: =(E41/E18) -> 0
B32: Other expense | J32: Earnings per share (EPS) | M32: =(E44) -> 1322885000
B33: Profit Before Taxes (looses) | E33: 2334846000 | J33: Return on Sales (ROS) | M33: =E41/E27 -> 0
B34: Income tax expense | E34: -591575000 | J34: Valuation ratios
B35: net income (looses) | E35: =(E33-E34) -> 2926421000 | J35: Price/earnings (P/E) ratios | M35: =(E55/M32) -> 0
B36: Total equity of the holding company | E36: 1589594000 | J36: Book Value Per Share (BVPS) | M36: =((E15-E24)/E50) -> 2.9255148
B37: non controlling interest | E37: =(E35-E36) -> 1336827000 | J37: Price-to-Book Value(P/B) Ratio | M37: =(E51/M36) -> 2.5636513
B38: earnings (loos) per shere | E38: =(E36/E50) -> 0.7277761
B39: add / (deduct)
B40: foreign currency gain or looses | E40: -79209000
B41: others Revenues
B42: Total comprehensive income | E42: =(E35+(E40+E41)) -> 2847212000
...

Sheet Sheet2
B3: ticker: | C3: ABUK | D3: =VLOOKUP(C3,SOURCE!$G$3:$H$104,2,FALSE) -> ابوقير للاسمدة والصناعات الكيماوية | J3: Liquidity ratios
B4: Consolidated Balance Sheet as at | E4: JUNE | F4: 2024 | G4: Q2 | J4: Current Ratio | M4: =(E14/E23) -> 0.46027964
B5: Assets | J5: Quick Ratio (Inventory) | M5: =((E14-E9)/E23) -> 0.38533953
B6: Non-current asset | J6: Quick Ratio (Accounts Receivable) | M6: =((E14-E10)/E23) -> 0.33577681
B7: Total Non-current assets | E7: 143429270000 | J7: Cash Ratio | M7: =(E12/E23) -> 0.081832716
B8: Current assets | J8: Net working capital | M8: =(E14-E23) -> -48592222000
B9: Inventory | E9: 6747024000 | J9: Net working capital ratio | M9: =(M8/E23) -> -0.53972036
B10: account and notes receivadles | E10: 11209266000 | J10: Debt ratios
B11: debtors and other depit balances | E11: 10869636000 | J11: Total Debt-to-Total Assets Ratio | M11: =(E24/E15) -> 0.7649
B12: cach and cach equivalents | E12: 7367581000 | J12: Total debt / Equity | M12: =(E24/E18) -> 3.2535092
B13: others | J13: Total current liabilities/ Equity | M13: =(E23/E18) -> 2.0714794
B14: Total Current assets | E14: 41439997000 | J14: Equity/Total Non-current assets | M14: =(E18/E7) -> 0.30302576
B15: Total assets | E15: =(E7+E14) -> 184869267000 | J15: Interest Coverage Ratio | M15: =(E31/E30) -> #DIV/0!
B16: Liabilities and Share holders equity | J16: Activity Ratios
B17: Share holders' Equity | J17: Inventory Turnover | M17: =(E28/E9) -> 3.2915244
B18: Total equity | E18: 43462764000 | J18: Days Inventory Outstanding (DIO) | M18: =(E56/M17) -> 82.028862
B19: Liabilities | J19: Accounts Receivable Turnover | M19: =(E27/E10) -> 2.3206245
B20: Non-current liabilities | J20: Days Sales Outstanding (DSO) | M20: =(E56/M19) -> 116.34799
B21: Total Non-cerrent liabilites | E21: 51374284000 | J21: Payable Turnover
B22: Current liabilities | J22: Days Payable Outstanding (DPO) | M22: =(M21/E56) -> 0
B23: Total cerrent liabilites | E23: 90032219000 | J23: Operating Cycle (oc) | M23: =M18+M20 -> 198.37686
B24: Total liabilities | E24: =(E21+E23) -> 141406503000 | J24: Cash Conversion Cycle (ccc) | M24: =((M18+M20)-M22) -> 198.37686
B25: Total liabilities and equity | E25: =(E18+E24) -> 184869267000 | J25: Total Non-current assets Turnover | M25: =(E27/E7) -> 0.18136115
B26: Income Statement for the period ended | E26: =(E4) -> JUNE | F26: =F4 -> 2024 | G26: =(G4) -> Q2 | J26: Total Current assets Turnover | M26: =(E27/E14) -> 0.62771474
B27: Total Revenue | E27: 26012497000 | J27: Total Asset Turnover | M27: =(E27/E15) -> 0.14070752
B28: Cost of Goods Sold | E28: 22207994000 | J28: Profitability ratios
B29: Gross Profit | E29: =(E27-E28) -> 3804503000 | J29: Gross Margin Ratio | M29: =(E29/E27) -> 0.14625674
B30: Other Revenues | J30: Return on Assets (ROA) | M30: =(E41/E15) -> 0
B31: interest expense | E31: -293704000 | J31: Return on Equity (ROE) | M31: =(E41/E18) -> 0
B32: Other expense | J32: Earnings per share (EPS) | M32: =(E44) -> 1322885000
B33: Profit Before Taxes (looses) | E33: 2334846000 | J33: Return on Sales (ROS) | M33: =E41/E27 -> 0
B34: Income tax expense | E34: -591575000 | J34: Valuation ratios
B35: net income (looses) | E35: =(E33-E34) -> 2926421000 | J35: Price/earnings (P/E) ratios | M35: =(E55/M32) -> 2.6464885e-08
B36: Total equity of the holding company | E36: 1589594000 | J36: Book Value Per Share (BVPS) | M36: =((E15-E24)/E50) -> 25.460422
B37: non controlling interest | E37: =(E35-E36) -> 1336827000 | J37: Price-to-Book Value(P/B) Ratio | M37: =(E51/M36) -> 1.2961293
B38: earnings (loos) per shere | E38: =(E36/E50) -> 0.9311818
B39: add / (deduct)
B40: foreign currency gain or looses | E40: -79209000
B41: others Revenues
B42: Total comprehensive income | E42: =(E35+(E40+E41)) -> 2847212000
...

Sheet Sheet3
B3: ticker: | C3: SKPC | D3: =VLOOKUP(C3,SOURCE!$G$3:$H$104,2,FALSE) -> سيدى كرير للبتروكيماويات - سيدبك | J3: Liquidity ratios
B4: Consolidated Balance Sheet as at | E4: JUNE | F4: 2024 | G4: H1 | J4: Current Ratio | M4: =(E14/E23) -> 1.230803
B5: Assets | J5: Quick Ratio (Inventory) | M5: =((E14-E9)/E23) -> 0.94921422
B6: Non-current asset | J6: Quick Ratio (Accounts Receivable) | M6: =((E14-E10)/E23) -> 0.93661877
B7: Total Non-current assets | E7: 14374014000 | J7: Cash Ratio | M7: =(E12/E23) -> 0.27753068
B8: Current assets | J8: Net working capital | M8: =(E14-E23) -> 8794259000
B9: Inventory | E9: 10729343000 | J9: Net working capital ratio | M9: =(M8/E23) -> 0.23080305
B10: account and notes receivadles | E10: 11209266000 | J10: Debt ratios
B11: debtors and other depit balances | E11: 8775293000 | J11: Total Debt-to-Total Assets Ratio | M11: =(E24/E15) -> 0.70039884
B12: cach and cach equivalents | E12: 10574716000 | J12: Total debt / Equity | M12: =(E24/E18) -> 2.3377709
B13: others | J13: Total current liabilities/ Equity | M13: =(E23/E18) -> 2.0756697
B14: Total Current assets | E14: 46897131000 | J14: Equity/Total Non-current assets | M14: =(E18/E7) -> 1.2770897
B15: Total assets | E15: =(E7+E14) -> 61271145000 | J15: Interest Coverage Ratio | M15: =(E33/E31) -> -7.9496568
B16: Liabilities and Share holders equity | J16: Activity Ratios
B17: Share holders' Equity | J17: Inventory Turnover | M17: =(E28/E9) -> 2.0698373
B18: Total equity | E18: 18356905000 | J18: Days Inventory Outstanding (DIO) | M18: =(E56/M17) -> 43.481679
B19: Liabilities | J19: Accounts Receivable Turnover | M19: =(E27/E10) -> 2.3206245
B20: Non-current liabilities | J20: Days Sales Outstanding (DSO) | M20: =(E56/M19) -> 38.782664
B21: Total Non-cerrent liabilites | E21: 4811367000 | J21: Payable Turnover
B22: Current liabilities | J22: Days Payable Outstanding (DPO) | M22: =(M21/E56) -> 0
B23: Total cerrent liabilites | E23: 38102872000 | J23: Operating Cycle (oc) | M23: =M18+M20 -> 82.264344
B24: Total liabilities | E24: =(E21+E23) -> 42914239000 | J24: Cash Conversion Cycle (ccc) | M24: =((M18+M20)-M22) -> 82.264344
B25: Total liabilities and equity | E25: =(E18+E24) -> 61271144000 | J25: Total Non-current assets Turnover | M25: =(E27/E7) -> 1.8096891
B26: Income Statement for the period ended | E26: =(E4) -> JUNE | F26: =F4 -> 2024 | G26: =(G4) -> H1 | J26: Total Current assets Turnover | M26: =(E27/E14) -> 0.55467139
B27: Total Revenue | E27: 26012497000 | J27: Total Asset Turnover | M27: =(E27/E15) -> 0.42454726
B28: Cost of Goods Sold | E28: 22207994000 | J28: Profitability ratios
B29: Gross Profit | E29: =(E27-E28) -> 3804503000 | J29: Gross Margin Ratio | M29: =(E29/E27) -> 0.14625674
B30: Other Revenues | J30: Return on Assets (ROA) | M30: =(E43/E15) -> 0.024878383
B31: interest expense | E31: -293704000 | J31: Return on Equity (ROE) | M31: =(E43/E18) -> 0.083038344
B32: Other expense | J32: Earnings per share (EPS) | M32: =(E46) -> 0.6978944
B33: Profit Before Taxes (looses) | E33: 2334846000 | J33: Return on Sales (ROS) | M33: =E43/E27 -> 0.058599795
B34: Income tax expense | E34: -591575000 | J34: Valuation ratios
B35: net income (looses) | E35: =(E33-E34) -> 2926421000 | J35: Price/earnings (P/E) ratios | M35: =(E55/M32) -> 0
B36: Total equity of the holding company | E36: 1589594000 | J36: Book Value Per Share (BVPS) | M36: =((E15-E24)/E50) -> 8.4044841
B37: non controlling interest | E37: =(E35-E36) -> 1336827000 | J37: Price-to-Book Value(P/B) Ratio | M37: =(E51/M36) -> 0.89238077
B38: earnings (loos) per shere | E38: =(E36/E50) -> 0.7277761
B39: add / (deduct)
B40: foreign currency gain or looses | E40: -79209000
B41: others Revenues
B42: Total comprehensive income | E42: =(E35+(E40+E41)) -> 2847212000
...

Sheet Sheet4
C7: ticker: | F7: =Sheet1!C3 -> HRHO | H7: =Sheet2!C3 -> ABUK | J7: =Sheet3!C3 -> SKPC
C8: date /period | F8: =Sheet1!E4 &Sheet1!F4 -> JUNE2024 | G8: =Sheet1!G4 -> YEAR | H8: =Sheet2!E4&Sheet2!F4 -> JUNE2024 | I8: =Sheet2!G4 -> Q2 | J8: =Sheet3!E4&Sheet3!F4 -> JUNE2024 | K8: =Sheet3!G4 -> H1
C9: Liquidity ratios
C10: Current Ratio | F10: =Sheet1!M4 -> 1.230803 | H10: =Sheet2!M4 -> 0.46027964 | J10: =Sheet3!M4 -> 1.230803
C11: Quick Ratio (Inventory) | F11: =Sheet1!M5 -> 0.94921422 | H11: =Sheet2!M5 -> 0.38533953 | J11: =Sheet3!M5 -> 0.94921422
C12: Quick Ratio (Accounts Receivable) | F12: =Sheet1!M6 -> 0.36114837 | H12: =Sheet2!M6 -> 0.33577681 | J12: =Sheet3!M6 -> 0.93661877
C13: Cash Ratio | F13: =Sheet1!M7 -> 0.27753068 | H13: =Sheet2!M7 -> 0.081832716 | J13: =Sheet3!M7 -> 0.27753068
C14: Net working capital | F14: =Sheet1!M8 -> 8794259000 | H14: =Sheet2!M8 -> -48592222000 | J14: =Sheet3!M8 -> 8794259000
C15: Net working capital ratio | F15: =Sheet1!M9 -> 0.23080305 | H15: =Sheet2!M9 -> -0.53972036 | J15: =Sheet3!M9 -> 0.23080305
C16: Debt ratios
C17: Total Debt-to-Total Assets Ratio | F17: =Sheet1!M11 -> 0.87039917 | H17: =Sheet2!M11 -> 0.7649 | J17: =Sheet3!M11 -> 0.70039884
C18: Total debt / Equity | F18: =Sheet1!M12 -> 2.3377709 | H18: =Sheet2!M12 -> 3.2535092 | J18: =Sheet3!M12 -> 2.3377709
C19: Total current liabilities/ Equity | F19: =Sheet1!M13 -> 2.0756697 | H19: =Sheet2!M13 -> 2.0714794 | J19: =Sheet3!M13 -> 2.0756697
C20: Equity/Total Non-current assets | F20: =Sheet1!M14 -> 7.6265965 | H20: =Sheet2!M14 -> 0.30302576 | J20: =Sheet3!M14 -> 1.2770897
C21: Interest Coverage Ratio | F21: =Sheet1!M15 -> #DIV/0! | H21: =Sheet2!M15 -> #DIV/0! | J21: =Sheet3!M15 -> -7.9496568
C22: Activity Ratios
C23: Inventory Turnover | F23: =Sheet1!M17 -> 2.0698373 | H23: =Sheet2!M17 -> 3.2915244 | J23: =Sheet3!M17 -> 2.0698373
C24: Days Inventory Outstanding (DIO) | F24: =Sheet1!M18 -> 43.481679 | H24: =Sheet2!M18 -> 82.028862 | J24: =Sheet3!M18 -> 43.481679
C25: Accounts Receivable Turnover | F25: =Sheet1!M19 -> 0.78501416 | H25: =Sheet2!M19 -> 2.3206245 | J25: =Sheet3!M19 -> 2.3206245
C26: Days Sales Outstanding (DSO) | F26: =Sheet1!M20 -> 114.64761 | H26: =Sheet2!M20 -> 116.34799 | J26: =Sheet3!M20 -> 38.782664
C27: Payable Turnover | F27: =Sheet1!M21 -> 0 | H27: =Sheet2!M21 -> 0 | J27: =Sheet3!M21 -> 0
C28: Days Payable Outstanding (DPO) | F28: =Sheet1!M22 -> 0 | H28: =Sheet2!M22 -> 0 | J28: =Sheet3!M22 -> 0
C29: Operating Cycle (oc) | F29: =Sheet1!M23 -> 158.12929 | H29: =Sheet2!M23 -> 198.37686 | J29: =Sheet3!M23 -> 82.264344
C30: Cash Conversion Cycle (ccc) | F30: =Sheet1!M24 -> 158.12929 | H30: =Sheet2!M24 -> 198.37686 | J30: =Sheet3!M24 -> 82.264344
C31: Total Non-current assets Turnover | F31: =Sheet1!M25 -> 10.807204 | H31: =Sheet2!M25 -> 0.18136115 | J31: =Sheet3!M25 -> 1.8096891
C32: Total Current assets Turnover | F32: =Sheet1!M26 -> 0.55467139 | H32: =Sheet2!M26 -> 0.62771474 | J32: =Sheet3!M26 -> 0.55467139
C33: Total Asset Turnover | F33: =Sheet1!M27 -> 0.52759309 | H33: =Sheet2!M27 -> 0.14070752 | J33: =Sheet3!M27 -> 0.42454726
C34: Profitability ratios
C35: Gross Margin Ratio | F35: =Sheet1!M29 -> 0.14625674 | H35: =Sheet2!M29 -> 0.14625674 | J35: =Sheet3!M29 -> 0.14625674
C36: Return on Assets (ROA) | F36: =Sheet1!M30 -> 0 | H36: =Sheet2!M30 -> 0 | J36: =Sheet3!M30 -> 0.024878383
C37: Return on Equity (ROE) | F37: =Sheet1!M31 -> 0 | H37: =Sheet2!M31 -> 0 | J37: =Sheet3!M31 -> 0.083038344
C38: Earnings per share (EPS) | F38: =Sheet1!M32 -> 1322885000 | H38: =Sheet2!M32 -> 1322885000 | J38: =Sheet3!M32 -> 0.6978944
C39: Return on Sales (ROS) | F39: =Sheet1!M33 -> 0 | H39: =Sheet2!M33 -> 0 | J39: =Sheet3!M33 -> 0.058599795
C40: Valuation ratios
C41: Price/earnings (P/E) ratios | F41: =Sheet1!M35 -> 0 | H41: =Sheet2!M35 -> 2.6464885e-08 | J41: =Sheet3!M35 -> 0
C42: Book Value Per Share (BVPS) | F42: =Sheet1!M36 -> 2.9255148 | H42: =Sheet2!M36 -> 25.460422 | J42: =Sheet3!M36 -> 8.4044841
C43: Price-to-Book Value(P/B) Ratio | F43: =Sheet1!M37 -> 2.5636513 | H43: =Sheet2!M37 -> 1.2961293 | J43: =Sheet3!M37 -> 0.89238077
C44: Other Data
C45: Shares Outstanding | F45: =Sheet1!E50 -> 2184180000 | H45: =Sheet2!E50 -> 1707071600 | J45: =Sheet3!E50 -> 2184180000
C46: Price, Current | F46: =Sheet1!E51 -> 7.5 | H46: =Sheet2!E51 -> 33 | J46: =Sheet3!E51 -> 7.5
...

Sheet SOURCE
B2: MONTH | C2: PERIOD | E2: YEAR | G2: ticker: | H2: اسم الشركه (EGX100) | J2: Column1
B3: MARCH | C3: Q1 | E3: 2015 | G3: AMER | H3: (مجموعة عامر القابضة (عامر جروب | J3: Consolidated Balance Sheet as at
B4: JUNE | C4: Q2 | E4: 2016 | G4: ATLC | H4: A.T.LEASEالتوفيق للتأجير التمويلي -أية.تي.ليس | J4: Standalone Balance Sheet as at
B5: SEPTEMBER | C5: Q3 | E5: 2017 | G5: RACC | H5: Raya Contact Centerراية لخدمات مراكز الاتصالات
B6: DECEMBER | C6: Q4 | E6: 2018 | G6: TALM | H6: Taaleem Management Services تعليم لخدمات الإدارة
C7: H1 | E7: 2019 | G7: ISPH | H7: ابن سينا فارما
C8: H2 | E8: 2020 | G8: ABUK | H8: ابوقير للاسمدة والصناعات الكيماوية
C9: YEAR | E9: 2021 | G9: AIH | H9: ارابيا انفستمنتس هولدنج
E10: 2022 | G10: ASCM | H10: اسيك للتعدين - اسكوم
E11: 2023 | G11: EMFD | H11: إعمار مصر للتنمية
E12: 2024 | G12: ALCN | H12: الاسكندرية لتداول الحاويات والبضائع
B13: PERIOD | C13: DAY | E13: 2025 | G13: AMOC | H13: الاسكندرية للزيوت المعدنية
B14: Q | C14: 90 | E14: 2026 | G14: ISMA | H14: الاسماعيلية مصر للدواجن
B15: H | C15: 180 | E15: 2027 | G15: COMI | H15: البنك التجاري الدولي -مصر (سى اى بى )
B16: 3Q | C16: 270 | E16: 2028 | G16: EXPA | H16: البنك المصري لتنمية الصادرات
B17: Y | C17: 360 | E17: 2029 | G17: GGCC | H17: الجيزةالعامة للمقاولات والاستثمارالعقارى
E18: 2030 | G18: ISMQ | H18: الحديد والصلب للمناجم والمحاجر
E19: 2031 | G19: MOIL | H19: الخدمات الملاحية والبترولية - ماريديف
E20: 2032 | G20: SUGR | H20: الدلتا للسكر
E21: 2033 | G21: IFAP | H21: الدوليه للمحاصيل الزراعيه
E22: 2034 | G22: OCDI | H22: السادس من اكتوبر للتنميه والاستثمار- سوديك
E23: 2035 | G23: SWDY | H23: السويدى اليكتريك
E24: 2036 | G24: EAST | H24: الشرقية - ايسترن كومباني
E25: 2037 | G25: ELSH | H25: الشمس للاسكان والتعمير
E26: 2038 | G26: UEGC | H26: الصعيد العامة للمقاولات والاستثمار العقاري SCCD
E27: 2039 | G27: EGCH | H27: الصناعات الكيماوية المصرية - كيما
E28: 2040 | G28: ENGC | H28: الصناعات الهندسية المعمارية للانشاء والتعمير - ايكون
E29: 2041 | G29: RMDA | H29: العاشر من رمضان للصناعات الدوائية والمستحضرات تشخيصية-راميدا
... E38: 2050 | G38: EKHOA | H38: القابضة المصرية الكويتية بالجنية
G39: POUL | H39: القاهرة للدواجن
G40: COSG | H40: القاهرة للزيوت والصابون
G41: CCAP | H41: القلعة للاستثمارات المالية
G42: CSAG | H42: القناة للتوكيلات الملاحية
G43: ELEC | H43: الكابلات الكهربائية المصرية
G44: EFIC | H44: المالية و الصناعية المصرية
G45: IEEC | H45: المشروعات الصناعية والهندسية
G46: PHAR | H46: المصرية الدولية للصناعات الدوائية - ايبيكو
G47: ETRS | H47: المصرية لخدمات النقل (ايجيترانس)
G48: ETEL | H48: المصرية للاتصالات
G49: EGTS | H49: المصرية للمنتجعات السياحية
...
